Workbook

Sheet Data brutes
A1: Batch | B1: Specifications | C1: Variety | D1: Start of production | E1: End of production | F1: Malt Yield R2 | G1: R2 Dry | H1: Goods Weight | I1: Goods Moisture | J1: Moisture Malt Quality | K1: FAN | L1: Friability | M1: Color EBC | N1: Betaglucans
A2: 705 | B2: 2RS | C2: TRAVELER | D2: 2024-02-20T00:00:00 | E2: 2024-02-28T00:00:00 | F2: 85.39 | H2: 283.31 | I2: 13.1
A3: 706 | B3: 2RS | C3: TRAVELER | D3: 2024-02-21T00:00:00 | E3: 2024-02-29T00:00:00 | F3: 85.6 | H3: 283.31 | I3: 13.1
A4: 707 | B4: 2RS | C4: TRAVELER | D4: 2024-02-22T00:00:00 | E4: 2024-03-01T00:00:00 | F4: 86.25 | G4: 94.5 | H4: 282.33999999999997 | I4: 12.8 | J4: 4.4800000000000004 | K4: 156 | L4: 82.08 | M4: 4 | N4: 283
A5: 708 | B5: 2RS | C5: TRAVELER | D5: 2024-02-23T00:00:00 | E5: 2024-03-02T00:00:00 | F5: 86.14 | G5: 91.9 | H5: 282.41000000000003 | I5: 10.4 | J5: 4.46 | K5: 153 | L5: 81.3 | M5: 4.4000000000000004 | N5: 267
A6: 709 | B6: 2RS | C6: TRAVELER | D6: 2024-02-25T00:00:00 | E6: 2024-03-04T00:00:00 | F6: 86.17 | G6: 94.6 | H6: 284.43 | I6: 12.7 | J6: 4.2 | K6: 135 | L6: 85.14 | M6: 3.6 | N6: 282
A7: 710 | B7: IBON | C7: IBON | D7: 2024-02-26T00:00:00 | E7: 2024-03-05T00:00:00 | F7: 83.07 | G7: 93.8 | H7: 283 | I7: 15.4 | J7: 4.4400000000000004 | K7: 135 | L7: 52 | M7: 4.0999999999999996 | N7: 367
A8: 711 | B8: 2RS | C8: TRAVELER | D8: 2024-02-27T00:00:00 | E8: 2024-03-06T00:00:00 | F8: 81.92 | G8: 87.6 | H8: 294.33999999999997 | I8: 10.5 | J8: 4.33 | K8: 113 | L8: 79.260000000000005 | M8: 4.5 | N8: 293
A9: 712 | B9: 2RS | C9: TRAVELER | D9: 2024-02-28T00:00:00 | E9: 2024-03-07T00:00:00 | F9: 85.64 | G9: 90.6 | H9: 282.41000000000003 | I9: 10.1 | J9: 4.8899999999999997 | K9: 144 | L9: 79.400000000000006 | M9: 4.5 | N9: 293
A10: 713 | B10: 2RS | C10: TRAVELER | D10: 2024-02-29T00:00:00 | E10: 2024-03-08T00:00:00 | F10: 85.74 | G10: 91.3 | H10: 282.64999999999998 | I10: 10.1 | J10: 4.3 | K10: 155 | L10: 90.42 | M10: 3.7 | N10: 108
A11: 714 | B11: 2RS | C11: TRAVELER | D11: 2024-03-01T00:00:00 | E11: 2024-03-09T00:00:00 | F11: 86.28 | G11: 94.7 | H11: 282.92 | I11: 12.9 | J11: 4.42 | K11: 147 | L11: 87.8 | M11: 4.0999999999999996 | N11: 186
A12: 715 | B12: 2RS | C12: TRAVELER | D12: 2024-03-02T00:00:00 | E12: 2024-03-10T00:00:00 | F12: 85.2 | G12: 93.8 | H12: 283.22000000000003 | I12: 13.6 | J12: 4.8899999999999997 | K12: 144 | L12: 79.400000000000006 | M12: 4.5 | N12: 293
A13: 716 | B13: 2RS | C13: TRAVELER | D13: 2024-03-04T00:00:00 | E13: 2024-03-12T00:00:00 | F13: 85.05 | G13: 94.2 | H13: 282.88 | I13: 13.6 | J13: 4.29 | K13: 154 | L13: 82 | M13: 4.8 | N13: 350
A14: 717 | B14: 2RS | C14: TRAVELER | D14: 2024-03-05T00:00:00 | E14: 2024-03-13T00:00:00 | F14: 85.03 | G14: 94 | H14: 282.79000000000002 | I14: 13.4 | J14: 4.29 | K14: 154 | L14: 82.68 | M14: 4.4000000000000004 | N14: 329
A15: 718 | B15: 2RS | C15: TRAVELER | D15: 2024-03-06T00:00:00 | E15: 2024-03-14T00:00:00 | F15: 84.44 | G15: 94.6 | H15: 287.06 | I15: 14.6 | J15: 4.3 | K15: 154 | L15: 82 | M15: 4.8 | N15: 350
... A73: 776 | B73: 2RS | C73: TRAVELER | D73: 2024-05-13T00:00:00 | E73: 2024-05-21T00:00:00 | F73: 83.23 | G73: 93.8 | H73: 286.58999999999997 | I73: 15 | J73: 4.2300000000000004 | K73: 121 | L73: 81 | M73: 3.7 | N73: 266
A74: 777 | B74: 2RS | C74: TRAVELER | D74: 2024-05-14T00:00:00 | E74: 2024-05-22T00:00:00 | F74: 82.67 | G74: 93.1 | H74: 286.58 | I74: 14.9 | J74: 4.2 | L74: 73.61 | N74: 405
A75: 778 | B75: 2RS | C75: TRAVELER | D75: 2024-05-15T00:00:00 | E75: 2024-05-23T00:00:00 | F75: 83.11 | G75: 93.2 | H75: 286.47000000000003 | I75: 14.7 | J75: 4.3099999999999996 | L75: 78.16 | N75: 320
A76: 779 | B76: 2RS | C76: TRAVELER | D76: 2024-05-16T00:00:00 | E76: 2024-05-24T00:00:00 | F76: 83.32 | G76: 93.4 | H76: 282.10000000000002 | I76: 14.5 | J76: 4.13 | L76: 75.099999999999994 | N76: 298
A77: 780 | B77: IBON | C77: IBON | D77: 2024-05-17T00:00:00 | E77: 2024-05-25T00:00:00 | F77: 83.33 | G77: 93.4 | H77: 282.55 | I77: 14.9 | J77: 4.6399999999999997 | L77: 56.96 | N77: 363
A78: 781 | B78: IBON | C78: IBON | D78: 2024-05-18T00:00:00 | E78: 2024-05-26T00:00:00 | F78: 83.08 | G78: 92.9 | H78: 282.33 | I78: 14.7 | J78: 4.59 | L78: 52.5 | N78: 414
A79: 782 | B79: IBON | C79: IBON | D79: 2024-05-19T00:00:00 | E79: 2024-05-27T00:00:00 | F79: 82.37 | G79: 92.2 | H79: 282.94 | I79: 14.5 | J79: 4.28 | L79: 57 | N79: 290
A80: 783 | B80: 2RS | C80: TRAVELER | D80: 2024-05-21T00:00:00 | E80: 2024-05-29T00:00:00 | F80: 83.45 | G80: 93.4 | H80: 286.89 | I80: 14.4 | J80: 4.16 | L80: 82.32 | N80: 249
A81: 784 | B81: 2RS | C81: TRAVELER | D81: 2024-05-22T00:00:00 | E81: 2024-05-30T00:00:00 | F81: 83.37 | H81: 285.60000000000002 | I81: 14.5
A82: 785 | B82: 2RS | C82: TRAVELER | D82: 2024-05-23T00:00:00 | E82: 2024-05-31T00:00:00 | F82: 83.32 | G82: 93.5 | H82: 287.75 | I82: 14.5 | J82: 4.0199999999999996 | L82: 81.239999999999995 | N82: 376
A83: 786 | B83: 2RS | C83: TRAVELER | D83: 2024-05-24T00:00:00 | E83: 2024-06-01T00:00:00 | F83: 82.98 | G83: 93.6 | H83: 286.91000000000003 | I83: 14.9 | J83: 4.0599999999999996 | L83: 82.21 | N83: 307
A84: 787 | B84: 2RS | C84: TRAVELER | D84: 2024-05-25T00:00:00 | E84: 2024-06-02T00:00:00 | F84: 82.82 | G84: 93.4 | H84: 286.5 | I84: 14.9 | J84: 4 | L84: 83.3 | N84: 362
A85: 788 | B85: 2RS | C85: TRAVELER | D85: 2024-05-26T00:00:00 | E85: 2024-06-03T00:00:00 | F85: 83.47 | G85: 93.6 | H85: 287.02999999999997 | I85: 14.6 | J85: 4.2699999999999996 | L85: 82.8 | N85: 289
A86: 789 | B86: 2RS | C86: TRAVELER | D86: 2024-05-27T00:00:00 | E86: 2024-06-04T00:00:00 | F86: 84.8 | G86: 94.5 | H86: 286.74 | I86: 14 | J86: 4.16 | L86: 82.74 | N86: 283
A87: 790 | B87: 2RS | C87: TRAVELER | D87: 2024-05-29T00:00:00 | E87: 2024-06-06T00:00:00 | F87: 83.67 | G87: 94 | H87: 286.63 | I87: 14.3 | J87: 3.75 | K87: 130 | L87: 81 | M87: 4.0999999999999996 | N87: 273
A88: 791 | B88: 2RS | C88: TRAVELER | D88: 2024-05-30T00:00:00 | E88: 2024-06-07T00:00:00 | F88: 84.77 | G88: 94.3 | H88: 286.74 | I88: 13.9 | J88: 4.2300000000000004 | K88: 132 | L88: 81.58 | M88: 3.79 | N88: 338
A89: 792 | B89: 2RS | C89: TRAVELER | D89: 2024-05-31T00:00:00 | E89: 2024-06-08T00:00:00 | F89: 84.16 | G89: 94.2 | H89: 286.19 | I89: 14.5 | J89: 4.28 | K89: 145 | L89: 85 | M89: 3.8 | N89: 192
A90: 793 | B90: IBON | C90: IBON | D90: 2024-06-01T00:00:00 | E90: 2024-06-09T00:00:00 | F90: 83.55 | G90: 93.2 | H90: 282.63 | I90: 14.2 | J90: 4.33 | K90: 157 | L90: 54.2 | M90: 5.3 | N90: 400
A91: 794 | B91: IBON | C91: IBON | D91: 2024-06-02T00:00:00 | E91: 2024-06-10T00:00:00 | F91: 83.4 | G91: 93 | H91: 283.19 | I91: 14.3 | J91: 4.46 | K91: 163 | L91: 52 | M91: 5.8 | N91: 333
A92: 795 | B92: IBON | C92: IBON | D92: 2024-06-03T00:00:00 | E92: 2024-06-11T00:00:00 | F92: 82.64 | G92: 92.3 | H92: 283.10000000000002 | I92: 14.4 | J92: 4.38 | K92: 167 | L92: 55.8 | M92: 5.6 | N92: 402
A93: 796 | B93: 2RS | C93: TRAVELER | D93: 2024-06-05T00:00:00 | E93: 2024-06-13T00:00:00 | F93: 84.17 | G93: 93.6 | H93: 287.57 | I93: 14 | J93: 4.34 | K93: 118 | L93: 83.12 | M93: 3.16 | N93: 252
A94: 797 | B94: 2RS | C94: TRAVELER | D94: 2024-06-06T00:00:00 | E94: 2024-06-14T00:00:00 | F94: 84.19 | G94: 93.8 | H94: 287.44 | I94: 14.1 | J94: 4.2699999999999996 | K94: 117 | L94: 79.34 | M94: 3.19 | N94: 305
A95: 798 | B95: 2RS | C95: TRAVELER | D95: 2024-06-07T00:00:00 | E95: 2024-06-15T00:00:00 | F95: 84.01 | G95: 93.7 | H95: 286.73 | I95: 14.3 | J95: 4.45 | K95: 119 | L95: 79.7 | M95: 3.25 | N95: 313
A96: 799 | B96: 2RS | C96: TRAVELER | D96: 2024-06-08T00:00:00 | E96: 2024-06-16T00:00:00 | F96: 83.55 | G96: 93.4 | H96: 286.89 | I96: 14.1 | J96: 3.94 | K96: 118 | L96: 82.94 | M96: 3.6 | N96: 297
A97: 800 | B97: 2RS | C97: TRAVELER | D97: 2024-06-09T00:00:00 | E97: 2024-06-17T00:00:00 | F97: 83.36 | G97: 93.1 | H97: 287.56 | I97: 13.9 | J97: 3.81 | K97: 120 | L97: 90.8 | M97: 3.4 | N97: 177
...

Sheet Data filtrees
A1: Batch | B1: Cahier des charges | C1: Mois | D1: Fin de production | E1: Cle | F1: malt_yield_r2 | G1: malt_dry_yield | H1: goods_weight | I1: goods_moisture | J1: malt_moisture | K1: FAN | L1: friabilite | M1: coloration_EBC | N1: betaG
A2: 705 | B2: 2RS | C2: 2 | D2: 45350 | E2: 2RS-2 | F2: 85.39 | H2: 283.31 | I2: 13.1
A3: 706 | B3: 2RS | C3: 2 | D3: 45351 | E3: 2RS-2 | F3: 85.6 | H3: 283.31 | I3: 13.1
A4: 707 | B4: 2RS | C4: 3 | D4: 45352 | E4: 2RS-3 | F4: 86.25 | G4: 94.5 | H4: 282.34 | I4: 12.8 | J4: 4.48 | K4: 156 | L4: 82.08 | M4: 4 | N4: 283
A5: 708 | B5: 2RS | C5: 3 | D5: 45353 | E5: 2RS-3 | F5: 86.14 | G5: 91.9 | H5: 282.41 | I5: 10.4 | J5: 4.46 | K5: 153 | L5: 81.3 | M5: 4.4 | N5: 267
A6: 709 | B6: 2RS | C6: 3 | D6: 45355 | E6: 2RS-3 | F6: 86.17 | G6: 94.6 | H6: 284.43 | I6: 12.7 | J6: 4.2 | K6: 135 | L6: 85.14 | M6: 3.6 | N6: 282
A7: 710 | B7: IBON | C7: 3 | D7: 45356 | E7: IBON-3 | F7: 83.07 | G7: 93.8 | H7: 283 | I7: 15.4 | J7: 4.44 | K7: 135 | L7: 52 | M7: 4.1 | N7: 367
A8: 711 | B8: 2RS | C8: 3 | D8: 45357 | E8: 2RS-3 | F8: 81.92 | G8: 87.6 | H8: 294.34 | I8: 10.5 | J8: 4.33 | K8: 113 | L8: 79.26 | M8: 4.5 | N8: 293
A9: 712 | B9: 2RS | C9: 3 | D9: 45358 | E9: 2RS-3 | F9: 85.64 | G9: 90.6 | H9: 282.41 | I9: 10.1 | J9: 4.89 | K9: 144 | L9: 79.4 | M9: 4.5 | N9: 293
A10: 713 | B10: 2RS | C10: 3 | D10: 45359 | E10: 2RS-3 | F10: 85.74 | G10: 91.3 | H10: 282.65 | I10: 10.1 | J10: 4.3 | K10: 155 | L10: 90.42 | M10: 3.7
A11: 714 | B11: 2RS | C11: 3 | D11: 45360 | E11: 2RS-3 | F11: 86.28 | G11: 94.7 | H11: 282.92 | I11: 12.9 | J11: 4.42 | K11: 147 | L11: 87.8 | M11: 4.1 | N11: 186
A12: 715 | B12: 2RS | C12: 3 | D12: 45361 | E12: 2RS-3 | F12: 85.2 | G12: 93.8 | H12: 283.22 | I12: 13.6 | J12: 4.89 | K12: 144 | L12: 79.4 | M12: 4.5 | N12: 293
A13: 716 | B13: 2RS | C13: 3 | D13: 45363 | E13: 2RS-3 | F13: 85.05 | G13: 94.2 | H13: 282.88 | I13: 13.6 | J13: 4.29 | K13: 154 | L13: 82 | M13: 4.8 | N13: 350
A14: 717 | B14: 2RS | C14: 3 | D14: 45364 | E14: 2RS-3 | F14: 85.03 | G14: 94 | H14: 282.79 | I14: 13.4 | J14: 4.29 | K14: 154 | L14: 82.68 | M14: 4.4 | N14: 329
A15: 718 | B15: 2RS | C15: 3 | D15: 45365 | E15: 2RS-3 | F15: 84.44 | G15: 94.6 | H15: 287.06 | I15: 14.6 | J15: 4.3 | K15: 154 | L15: 82 | M15: 4.8 | N15: 350
A16: 719 | B16: IBON | C16: 3 | D16: 45366 | E16: IBON-3 | F16: 83.43 | G16: 94.9 | H16: 275.43 | I16: 15.9 | J16: 4.32 | K16: 142 | L16: 54.7 | M16: 4.2 | N16: 329
A17: 720 | B17: 2RS | C17: 3 | D17: 45367 | E17: 2RS-3 | F17: 85.48 | G17: 94.7 | H17: 283.21 | I17: 13.4 | J17: 4.1 | K17: 151 | L17: 82.8 | M17: 4.29 | N17: 311
A18: 721 | B18: IBON | C18: 3 | D18: 45368 | E18: IBON-3 | F18: 84.06 | G18: 94.7 | I18: 15.2 | J18: 4.43 | K18: 137 | L18: 52 | M18: 4.4
A19: 722 | B19: 2RS | C19: 3 | D19: 45369 | E19: 2RS-3 | F19: 85.17 | G19: 94.6 | H19: 286.99 | I19: 13.7 | J19: 4.14 | K19: 153 | L19: 84.32 | M19: 4.8 | N19: 324
A20: 723 | B20: 2RS | C20: 3 | D20: 45371 | E20: 2RS-3 | F20: 84.87 | G20: 95.4 | H20: 283.35 | I20: 14.9 | J20: 4.39 | K20: 129 | L20: 78 | M20: 3.9 | N20: 420
A21: 724 | B21: IBON | C21: 3 | D21: 45372 | E21: IBON-3 | F21: 83.38 | G21: 91.3 | I21: 12.5 | J21: 4.16 | K21: 135 | L21: 56.2 | M21: 4.2
A22: 725 | B22: IBON | C22: 3 | D22: 45373 | E22: IBON-3 | F22: 83.21 | G22: 94.2 | I22: 15.6 | J22: 4.42 | K22: 142 | L22: 52.8 | M22: 3.4
A23: 726 | B23: IBON | C23: 3 | D23: 45374 | E23: IBON-3 | F23: 83.32 | G23: 94 | I23: 15 | J23: 4.15 | K23: 155 | L23: 58.1 | M23: 4.7 | N23: 302
A24: 727 | B24: IBON | C24: 3 | D24: 45375 | E24: IBON-3 | F24: 83.35 | G24: 94.1 | H24: 275.12 | I24: 15.2 | J24: 4.27 | K24: 144 | L24: 52 | M24: 3.8 | N24: 388
A25: 728 | B25: IBON | C25: 3 | D25: 45376 | E25: IBON-3 | F25: 83.8 | G25: 94.2 | I25: 15 | J25: 4.47 | K25: 137 | L25: 49 | M25: 3.6 | N25: 425
A26: 729 | B26: 2RS | C26: 3 | D26: 45378 | E26: 2RS-3 | F26: 84.13 | G26: 94.4 | H26: 282.76 | I26: 14.9 | J26: 4.55 | K26: 138 | L26: 81 | M26: 3.34 | N26: 267
A27: 730 | B27: 2RS | C27: 3 | D27: 45379 | E27: 2RS-3 | F27: 84.06 | G27: 94.8 | H27: 287.72 | I27: 15.1 | J27: 4.29 | K27: 115 | L27: 82.2 | M27: 3.4 | N27: 292
A28: 731 | B28: 2RS | C28: 3 | D28: 45380 | E28: 2RS-3 | F28: 84.01 | G28: 94.4 | H28: 286.75 | I28: 14.9 | J28: 4.34 | K28: 126 | L28: 83.48 | M28: 4 | N28: 188
A29: 732 | B29: 2RS | C29: 3 | D29: 45381 | E29: 2RS-3 | F29: 85.14 | G29: 95.4 | H29: 283.06 | I29: 14.6 | J29: 4.31 | K29: 132 | L29: 84.28 | M29: 3.88 | N29: 178
A30: 733 | B30: 2RS | C30: 3 | D30: 45382 | E30: 2RS-3 | F30: 86.26 | G30: 96.3 | H30: 287.1 | I30: 14.5 | J30: 4.52 | K30: 130 | L30: 87 | M30: 4.2 | N30: 150
A31: 734 | B31: 2RS | C31: 4 | D31: 45383 | E31: 2RS-4 | F31: 83.47 | G31: 93.7 | H31: 287.9 | I31: 14.8 | J31: 4.36 | K31: 124 | L31: 84.2 | M31: 4.15 | N31: 172
A32: 735 | B32: 2RS | C32: 4 | D32: 45384 | E32: 2RS-4 | F32: 82.81 | G32: 92.7 | H32: 286.89 | I32: 14.8 | J32: 4.61 | K32: 138 | L32: 82.48 | M32: 4.5 | N32: 154
A33: 736 | B33: 2RS | C33: 4 | D33: 45385 | E33: 2RS-4 | F33: 84.16 | G33: 94 | H33: 286.34 | I33: 14.3 | J33: 4.32 | K33: 128 | L33: 83.12 | M33: 3.9 | N33: 203
A34: 737 | B34: 2RS | C34: 4 | D34: 45387 | E34: 2RS-4 | F34: 83.24 | G34: 93.4 | H34: 286.97 | I34: 14.8 | J34: 4.4 | K34: 138 | L34: 84.9 | M34: 4.1 | N34: 145
A35: 738 | B35: 2RS | C35: 4 | D35: 45388 | E35: 2RS-4 | F35: 83.33 | G35: 93.8 | H35: 286.49 | I35: 14.9 | J35: 4.24 | K35: 133 | L35: 84.76 | M35: 4.09 | N35: 170
A36: 739 | B36: 2RS | C36: 4 | D36: 45390 | E36: 2RS-4 | F36: 83.68 | G36: 93.7 | H36: 285.75 | I36: 14.7 | J36: 4.53 | K36: 137 | L36: 84.96 | M36: 3.89 | N36: 175
A37: 740 | B37: 2RS | C37: 4 | D37: 45391 | E37: 2RS-4 | F37: 84.29 | G37: 94.7 | H37: 285.92 | I37: 15 | J37: 4.47 | K37: 134 | L37: 81.22 | M37: 3.86 | N37: 208
... A73: 776 | B73: 2RS | C73: 5 | D73: 45433 | E73: 2RS-5 | F73: 83.23 | G73: 93.8 | H73: 286.59 | I73: 15 | J73: 4.23 | K73: 121 | L73: 81 | M73: 3.7 | N73: 266
A74: 777 | B74: 2RS | C74: 5 | D74: 45434 | E74: 2RS-5 | F74: 82.67 | G74: 93.1 | H74: 286.58 | I74: 14.9 | J74: 4.2 | L74: 73.61 | N74: 405
A75: 778 | B75: 2RS | C75: 5 | D75: 45435 | E75: 2RS-5 | F75: 83.11 | G75: 93.2 | H75: 286.47 | I75: 14.7 | J75: 4.31 | L75: 78.16 | N75: 320
...

Sheet NB
A1: Nombre de couches par cahier des charges et par mois de fin de production
A2: NB | B2: 1 | C2: 2 | D2: 3 | E2: 4 | F2: 5 | G2: 6 | H2: 7 | I2: 8 | J2: 9 | K2: 10 | L2: 11 | M2: 12
A3: 2RS | B3: =COUNTIFS('Data filtrees'!$B$2:$B$618,$A3,'Data filtrees'!$C$2:$C$618,1,'Data filtrees'!$F$2:$F$618,"<>") | C3: =COUNTIFS('Data filtrees'!$B$2:$B$618,$A3,'Data filtrees'!$C$2:$C$618,2,'Data filtrees'!$F$2:$F$618,"<>") | D3: =COUNTIFS('Data filtrees'!$B$2:$B$618,$A3,'Data filtrees'!$C$2:$C$618,3,'Data filtrees'!$F$2:$F$618,"<>") | E3: =COUNTIFS('Data filtrees'!$B$2:$B$618,$A3,'Data filtrees'!$C$2:$C$618,4,'Data filtrees'!$F$2:$F$618,"<>") | F3: =COUNTIFS('Data filtrees'!$B$2:$B$618,$A3,'Data filtrees'!$C$2:$C$618,5,'Data filtrees'!$F$2:$F$618,"<>") | G3: =COUNTIFS('Data filtrees'!$B$2:$B$618,$A3,'Data filtrees'!$C$2:$C$618,6,'Data filtrees'!$F$2:$F$618,"<>") | H3: =COUNTIFS('Data filtrees'!$B$2:$B$618,$A3,'Data filtrees'!$C$2:$C$618,7,'Data filtrees'!$F$2:$F$618,"<>") | I3: =COUNTIFS('Data filtrees'!$B$2:$B$618,$A3,'Data filtrees'!$C$2:$C$618,8,'Data filtrees'!$F$2:$F$618,"<>") | J3: =COUNTIFS('Data filtrees'!$B$2:$B$618,$A3,'Data filtrees'!$C$2:$C$618,9,'Data filtrees'!$F$2:$F$618,"<>") | K3: =COUNTIFS('Data filtrees'!$B$2:$B$618,$A3,'Data filtrees'!$C$2:$C$618,10,'Data filtrees'!$F$2:$F$618,"<>") | L3: =COUNTIFS('Data filtrees'!$B$2:$B$618,$A3,'Data filtrees'!$C$2:$C$618,11,'Data filtrees'!$F$2:$F$618,"<>") | M3: =COUNTIFS('Data filtrees'!$B$2:$B$618,$A3,'Data filtrees'!$C$2:$C$618,12,'Data filtrees'!$F$2:$F$618,"<>")
A4: IBON | B4: =COUNTIFS('Data filtrees'!$B$2:$B$618,$A4,'Data filtrees'!$C$2:$C$618,1,'Data filtrees'!$F$2:$F$618,"<>") | C4: =COUNTIFS('Data filtrees'!$B$2:$B$618,$A4,'Data filtrees'!$C$2:$C$618,2,'Data filtrees'!$F$2:$F$618,"<>") | D4: =COUNTIFS('Data filtrees'!$B$2:$B$618,$A4,'Data filtrees'!$C$2:$C$618,3,'Data filtrees'!$F$2:$F$618,"<>") | E4: =COUNTIFS('Data filtrees'!$B$2:$B$618,$A4,'Data filtrees'!$C$2:$C$618,4,'Data filtrees'!$F$2:$F$618,"<>") | F4: =COUNTIFS('Data filtrees'!$B$2:$B$618,$A4,'Data filtrees'!$C$2:$C$618,5,'Data filtrees'!$F$2:$F$618,"<>") | G4: =COUNTIFS('Data filtrees'!$B$2:$B$618,$A4,'Data filtrees'!$C$2:$C$618,6,'Data filtrees'!$F$2:$F$618,"<>") | H4: =COUNTIFS('Data filtrees'!$B$2:$B$618,$A4,'Data filtrees'!$C$2:$C$618,7,'Data filtrees'!$F$2:$F$618,"<>") | I4: =COUNTIFS('Data filtrees'!$B$2:$B$618,$A4,'Data filtrees'!$C$2:$C$618,8,'Data filtrees'!$F$2:$F$618,"<>") | J4: =COUNTIFS('Data filtrees'!$B$2:$B$618,$A4,'Data filtrees'!$C$2:$C$618,9,'Data filtrees'!$F$2:$F$618,"<>") | K4: =COUNTIFS('Data filtrees'!$B$2:$B$618,$A4,'Data filtrees'!$C$2:$C$618,10,'Data filtrees'!$F$2:$F$618,"<>") | L4: =COUNTIFS('Data filtrees'!$B$2:$B$618,$A4,'Data filtrees'!$C$2:$C$618,11,'Data filtrees'!$F$2:$F$618,"<>") | M4: =COUNTIFS('Data filtrees'!$B$2:$B$618,$A4,'Data filtrees'!$C$2:$C$618,12,'Data filtrees'!$F$2:$F$618,"<>")
A6: Rouge = moins de 5 couches : la moyenne du casier n'est pas retenue, on prend celle du mois entier.

Sheet malt_yield_r2
A1: Rendement humide R2 — nombre de couches, puis moyenne
A2: NB | B2: 1 | C2: 2 | D2: 3 | E2: 4 | F2: 5 | G2: 6 | H2: 7 | I2: 8 | J2: 9 | K2: 10 | L2: 11 | M2: 12
A3: 2RS | B3: =COUNTIFS('Data filtrees'!$B$2:$B$618,$A3,'Data filtrees'!$C$2:$C$618,1,'Data filtrees'!$F$2:$F$618,"<>") | C3: =COUNTIFS('Data filtrees'!$B$2:$B$618,$A3,'Data filtrees'!$C$2:$C$618,2,'Data filtrees'!$F$2:$F$618,"<>") | D3: =COUNTIFS('Data filtrees'!$B$2:$B$618,$A3,'Data filtrees'!$C$2:$C$618,3,'Data filtrees'!$F$2:$F$618,"<>") | E3: =COUNTIFS('Data filtrees'!$B$2:$B$618,$A3,'Data filtrees'!$C$2:$C$618,4,'Data filtrees'!$F$2:$F$618,"<>") | F3: =COUNTIFS('Data filtrees'!$B$2:$B$618,$A3,'Data filtrees'!$C$2:$C$618,5,'Data filtrees'!$F$2:$F$618,"<>") | G3: =COUNTIFS('Data filtrees'!$B$2:$B$618,$A3,'Data filtrees'!$C$2:$C$618,6,'Data filtrees'!$F$2:$F$618,"<>") | H3: =COUNTIFS('Data filtrees'!$B$2:$B$618,$A3,'Data filtrees'!$C$2:$C$618,7,'Data filtrees'!$F$2:$F$618,"<>") | I3: =COUNTIFS('Data filtrees'!$B$2:$B$618,$A3,'Data filtrees'!$C$2:$C$618,8,'Data filtrees'!$F$2:$F$618,"<>") | J3: =COUNTIFS('Data filtrees'!$B$2:$B$618,$A3,'Data filtrees'!$C$2:$C$618,9,'Data filtrees'!$F$2:$F$618,"<>") | K3: =COUNTIFS('Data filtrees'!$B$2:$B$618,$A3,'Data filtrees'!$C$2:$C$618,10,'Data filtrees'!$F$2:$F$618,"<>") | L3: =COUNTIFS('Data filtrees'!$B$2:$B$618,$A3,'Data filtrees'!$C$2:$C$618,11,'Data filtrees'!$F$2:$F$618,"<>") | M3: =COUNTIFS('Data filtrees'!$B$2:$B$618,$A3,'Data filtrees'!$C$2:$C$618,12,'Data filtrees'!$F$2:$F$618,"<>")
A4: IBON | B4: =COUNTIFS('Data filtrees'!$B$2:$B$618,$A4,'Data filtrees'!$C$2:$C$618,1,'Data filtrees'!$F$2:$F$618,"<>") | C4: =COUNTIFS('Data filtrees'!$B$2:$B$618,$A4,'Data filtrees'!$C$2:$C$618,2,'Data filtrees'!$F$2:$F$618,"<>") | D4: =COUNTIFS('Data filtrees'!$B$2:$B$618,$A4,'Data filtrees'!$C$2:$C$618,3,'Data filtrees'!$F$2:$F$618,"<>") | E4: =COUNTIFS('Data filtrees'!$B$2:$B$618,$A4,'Data filtrees'!$C$2:$C$618,4,'Data filtrees'!$F$2:$F$618,"<>") | F4: =COUNTIFS('Data filtrees'!$B$2:$B$618,$A4,'Data filtrees'!$C$2:$C$618,5,'Data filtrees'!$F$2:$F$618,"<>") | G4: =COUNTIFS('Data filtrees'!$B$2:$B$618,$A4,'Data filtrees'!$C$2:$C$618,6,'Data filtrees'!$F$2:$F$618,"<>") | H4: =COUNTIFS('Data filtrees'!$B$2:$B$618,$A4,'Data filtrees'!$C$2:$C$618,7,'Data filtrees'!$F$2:$F$618,"<>") | I4: =COUNTIFS('Data filtrees'!$B$2:$B$618,$A4,'Data filtrees'!$C$2:$C$618,8,'Data filtrees'!$F$2:$F$618,"<>") | J4: =COUNTIFS('Data filtrees'!$B$2:$B$618,$A4,'Data filtrees'!$C$2:$C$618,9,'Data filtrees'!$F$2:$F$618,"<>") | K4: =COUNTIFS('Data filtrees'!$B$2:$B$618,$A4,'Data filtrees'!$C$2:$C$618,10,'Data filtrees'!$F$2:$F$618,"<>") | L4: =COUNTIFS('Data filtrees'!$B$2:$B$618,$A4,'Data filtrees'!$C$2:$C$618,11,'Data filtrees'!$F$2:$F$618,"<>") | M4: =COUNTIFS('Data filtrees'!$B$2:$B$618,$A4,'Data filtrees'!$C$2:$C$618,12,'Data filtrees'!$F$2:$F$618,"<>")
A6: MOYENNE | B6: 1 | C6: 2 | D6: 3 | E6: 4 | F6: 5 | G6: 6 | H6: 7 | I6: 8 | J6: 9 | K6: 10 | L6: 11 | M6: 12
A7: 2RS | B7: =IF(B3>=5,AVERAGEIFS('Data filtrees'!$F$2:$F$618,'Data filtrees'!$B$2:$B$618,$A3,'Data filtrees'!$C$2:$C$618,1),AVERAGEIFS('Data filtrees'!$F$2:$F$618,'Data filtrees'!$C$2:$C$618,1)) | C7: =IF(C3>=5,AVERAGEIFS('Data filtrees'!$F$2:$F$618,'Data filtrees'!$B$2:$B$618,$A3,'Data filtrees'!$C$2:$C$618,2),AVERAGEIFS('Data filtrees'!$F$2:$F$618,'Data filtrees'!$C$2:$C$618,2)) | D7: =IF(D3>=5,AVERAGEIFS('Data filtrees'!$F$2:$F$618,'Data filtrees'!$B$2:$B$618,$A3,'Data filtrees'!$C$2:$C$618,3),AVERAGEIFS('Data filtrees'!$F$2:$F$618,'Data filtrees'!$C$2:$C$618,3)) | E7: =IF(E3>=5,AVERAGEIFS('Data filtrees'!$F$2:$F$618,'Data filtrees'!$B$2:$B$618,$A3,'Data filtrees'!$C$2:$C$618,4),AVERAGEIFS('Data filtrees'!$F$2:$F$618,'Data filtrees'!$C$2:$C$618,4)) | F7: =IF(F3>=5,AVERAGEIFS('Data filtrees'!$F$2:$F$618,'Data filtrees'!$B$2:$B$618,$A3,'Data filtrees'!$C$2:$C$618,5),AVERAGEIFS('Data filtrees'!$F$2:$F$618,'Data filtrees'!$C$2:$C$618,5)) | G7: =IF(G3>=5,AVERAGEIFS('Data filtrees'!$F$2:$F$618,'Data filtrees'!$B$2:$B$618,$A3,'Data filtrees'!$C$2:$C$618,6),AVERAGEIFS('Data filtrees'!$F$2:$F$618,'Data filtrees'!$C$2:$C$618,6)) | H7: =IF(H3>=5,AVERAGEIFS('Data filtrees'!$F$2:$F$618,'Data filtrees'!$B$2:$B$618,$A3,'Data filtrees'!$C$2:$C$618,7),AVERAGEIFS('Data filtrees'!$F$2:$F$618,'Data filtrees'!$C$2:$C$618,7)) | I7: =IF(I3>=5,AVERAGEIFS('Data filtrees'!$F$2:$F$618,'Data filtrees'!$B$2:$B$618,$A3,'Data filtrees'!$C$2:$C$618,8),AVERAGEIFS('Data filtrees'!$F$2:$F$618,'Data filtrees'!$C$2:$C$618,8)) | J7: =IF(J3>=5,AVERAGEIFS('Data filtrees'!$F$2:$F$618,'Data filtrees'!$B$2:$B$618,$A3,'Data filtrees'!$C$2:$C$618,9),AVERAGEIFS('Data filtrees'!$F$2:$F$618,'Data filtrees'!$C$2:$C$618,9)) | K7: =IF(K3>=5,AVERAGEIFS('Data filtrees'!$F$2:$F$618,'Data filtrees'!$B$2:$B$618,$A3,'Data filtrees'!$C$2:$C$618,10),AVERAGEIFS('Data filtrees'!$F$2:$F$618,'Data filtrees'!$C$2:$C$618,10)) | L7: =IF(L3>=5,AVERAGEIFS('Data filtrees'!$F$2:$F$618,'Data filtrees'!$B$2:$B$618,$A3,'Data filtrees'!$C$2:$C$618,11),AVERAGEIFS('Data filtrees'!$F$2:$F$618,'Data filtrees'!$C$2:$C$618,11)) | M7: =IF(M3>=5,AVERAGEIFS('Data filtrees'!$F$2:$F$618,'Data filtrees'!$B$2:$B$618,$A3,'Data filtrees'!$C$2:$C$618,12),AVERAGEIFS('Data filtrees'!$F$2:$F$618,'Data filtrees'!$C$2:$C$618,12))
A8: IBON | B8: =IF(B4>=5,AVERAGEIFS('Data filtrees'!$F$2:$F$618,'Data filtrees'!$B$2:$B$618,$A4,'Data filtrees'!$C$2:$C$618,1),AVERAGEIFS('Data filtrees'!$F$2:$F$618,'Data filtrees'!$C$2:$C$618,1)) | C8: =IF(C4>=5,AVERAGEIFS('Data filtrees'!$F$2:$F$618,'Data filtrees'!$B$2:$B$618,$A4,'Data filtrees'!$C$2:$C$618,2),AVERAGEIFS('Data filtrees'!$F$2:$F$618,'Data filtrees'!$C$2:$C$618,2)) | D8: =IF(D4>=5,AVERAGEIFS('Data filtrees'!$F$2:$F$618,'Data filtrees'!$B$2:$B$618,$A4,'Data filtrees'!$C$2:$C$618,3),AVERAGEIFS('Data filtrees'!$F$2:$F$618,'Data filtrees'!$C$2:$C$618,3)) | E8: =IF(E4>=5,AVERAGEIFS('Data filtrees'!$F$2:$F$618,'Data filtrees'!$B$2:$B$618,$A4,'Data filtrees'!$C$2:$C$618,4),AVERAGEIFS('Data filtrees'!$F$2:$F$618,'Data filtrees'!$C$2:$C$618,4)) | F8: =IF(F4>=5,AVERAGEIFS('Data filtrees'!$F$2:$F$618,'Data filtrees'!$B$2:$B$618,$A4,'Data filtrees'!$C$2:$C$618,5),AVERAGEIFS('Data filtrees'!$F$2:$F$618,'Data filtrees'!$C$2:$C$618,5)) | G8: =IF(G4>=5,AVERAGEIFS('Data filtrees'!$F$2:$F$618,'Data filtrees'!$B$2:$B$618,$A4,'Data filtrees'!$C$2:$C$618,6),AVERAGEIFS('Data filtrees'!$F$2:$F$618,'Data filtrees'!$C$2:$C$618,6)) | H8: =IF(H4>=5,AVERAGEIFS('Data filtrees'!$F$2:$F$618,'Data filtrees'!$B$2:$B$618,$A4,'Data filtrees'!$C$2:$C$618,7),AVERAGEIFS('Data filtrees'!$F$2:$F$618,'Data filtrees'!$C$2:$C$618,7)) | I8: =IF(I4>=5,AVERAGEIFS('Data filtrees'!$F$2:$F$618,'Data filtrees'!$B$2:$B$618,$A4,'Data filtrees'!$C$2:$C$618,8),AVERAGEIFS('Data filtrees'!$F$2:$F$618,'Data filtrees'!$C$2:$C$618,8)) | J8: =IF(J4>=5,AVERAGEIFS('Data filtrees'!$F$2:$F$618,'Data filtrees'!$B$2:$B$618,$A4,'Data filtrees'!$C$2:$C$618,9),AVERAGEIFS('Data filtrees'!$F$2:$F$618,'Data filtrees'!$C$2:$C$618,9)) | K8: =IF(K4>=5,AVERAGEIFS('Data filtrees'!$F$2:$F$618,'Data filtrees'!$B$2:$B$618,$A4,'Data filtrees'!$C$2:$C$618,10),AVERAGEIFS('Data filtrees'!$F$2:$F$618,'Data filtrees'!$C$2:$C$618,10)) | L8: =IF(L4>=5,AVERAGEIFS('Data filtrees'!$F$2:$F$618,'Data filtrees'!$B$2:$B$618,$A4,'Data filtrees'!$C$2:$C$618,11),AVERAGEIFS('Data filtrees'!$F$2:$F$618,'Data filtrees'!$C$2:$C$618,11)) | M8: =IF(M4>=5,AVERAGEIFS('Data filtrees'!$F$2:$F$618,'Data filtrees'!$B$2:$B$618,$A4,'Data filtrees'!$C$2:$C$618,12),AVERAGEIFS('Data filtrees'!$F$2:$F$618,'Data filtrees'!$C$2:$C$618,12))
A9: monthly_average | B9: =AVERAGEIFS('Data filtrees'!$F$2:$F$618,'Data filtrees'!$C$2:$C$618,1) | C9: =AVERAGEIFS('Data filtrees'!$F$2:$F$618,'Data filtrees'!$C$2:$C$618,2) | D9: =AVERAGEIFS('Data filtrees'!$F$2:$F$618,'Data filtrees'!$C$2:$C$618,3) | E9: =AVERAGEIFS('Data filtrees'!$F$2:$F$618,'Data filtrees'!$C$2:$C$618,4) | F9: =AVERAGEIFS('Data filtrees'!$F$2:$F$618,'Data filtrees'!$C$2:$C$618,5) | G9: =AVERAGEIFS('Data filtrees'!$F$2:$F$618,'Data filtrees'!$C$2:$C$618,6) | H9: =AVERAGEIFS('Data filtrees'!$F$2:$F$618,'Data filtrees'!$C$2:$C$618,7) | I9: =AVERAGEIFS('Data filtrees'!$F$2:$F$618,'Data filtrees'!$C$2:$C$618,8) | J9: =AVERAGEIFS('Data filtrees'!$F$2:$F$618,'Data filtrees'!$C$2:$C$618,9) | K9: =AVERAGEIFS('Data filtrees'!$F$2:$F$618,'Data filtrees'!$C$2:$C$618,10) | L9: =AVERAGEIFS('Data filtrees'!$F$2:$F$618,'Data filtrees'!$C$2:$C$618,11) | M9: =AVERAGEIFS('Data filtrees'!$F$2:$F$618,'Data filtrees'!$C$2:$C$618,12)
A11: Au moins 5 couches : moyenne du cahier des charges. En dessous : moyenne du mois, tous cahiers des charges confondus.

Sheet malt_dry_yield
A1: Rendement sec — nombre de couches, puis moyenne
A2: NB | B2: 1 | C2: 2 | D2: 3 | E2: 4 | F2: 5 | G2: 6 | H2: 7 | I2: 8 | J2: 9 | K2: 10 | L2: 11 | M2: 12
A3: 2RS | B3: =COUNTIFS('Data filtrees'!$B$2:$B$618,$A3,'Data filtrees'!$C$2:$C$618,1,'Data filtrees'!$G$2:$G$618,"<>") | C3: =COUNTIFS('Data filtrees'!$B$2:$B$618,$A3,'Data filtrees'!$C$2:$C$618,2,'Data filtrees'!$G$2:$G$618,"<>") | D3: =COUNTIFS('Data filtrees'!$B$2:$B$618,$A3,'Data filtrees'!$C$2:$C$618,3,'Data filtrees'!$G$2:$G$618,"<>") | E3: =COUNTIFS('Data filtrees'!$B$2:$B$618,$A3,'Data filtrees'!$C$2:$C$618,4,'Data filtrees'!$G$2:$G$618,"<>") | F3: =COUNTIFS('Data filtrees'!$B$2:$B$618,$A3,'Data filtrees'!$C$2:$C$618,5,'Data filtrees'!$G$2:$G$618,"<>") | G3: =COUNTIFS('Data filtrees'!$B$2:$B$618,$A3,'Data filtrees'!$C$2:$C$618,6,'Data filtrees'!$G$2:$G$618,"<>") | H3: =COUNTIFS('Data filtrees'!$B$2:$B$618,$A3,'Data filtrees'!$C$2:$C$618,7,'Data filtrees'!$G$2:$G$618,"<>") | I3: =COUNTIFS('Data filtrees'!$B$2:$B$618,$A3,'Data filtrees'!$C$2:$C$618,8,'Data filtrees'!$G$2:$G$618,"<>") | J3: =COUNTIFS('Data filtrees'!$B$2:$B$618,$A3,'Data filtrees'!$C$2:$C$618,9,'Data filtrees'!$G$2:$G$618,"<>") | K3: =COUNTIFS('Data filtrees'!$B$2:$B$618,$A3,'Data filtrees'!$C$2:$C$618,10,'Data filtrees'!$G$2:$G$618,"<>") | L3: =COUNTIFS('Data filtrees'!$B$2:$B$618,$A3,'Data filtrees'!$C$2:$C$618,11,'Data filtrees'!$G$2:$G$618,"<>") | M3: =COUNTIFS('Data filtrees'!$B$2:$B$618,$A3,'Data filtrees'!$C$2:$C$618,12,'Data filtrees'!$G$2:$G$618,"<>")
A4: IBON | B4: =COUNTIFS('Data filtrees'!$B$2:$B$618,$A4,'Data filtrees'!$C$2:$C$618,1,'Data filtrees'!$G$2:$G$618,"<>") | C4: =COUNTIFS('Data filtrees'!$B$2:$B$618,$A4,'Data filtrees'!$C$2:$C$618,2,'Data filtrees'!$G$2:$G$618,"<>") | D4: =COUNTIFS('Data filtrees'!$B$2:$B$618,$A4,'Data filtrees'!$C$2:$C$618,3,'Data filtrees'!$G$2:$G$618,"<>") | E4: =COUNTIFS('Data filtrees'!$B$2:$B$618,$A4,'Data filtrees'!$C$2:$C$618,4,'Data filtrees'!$G$2:$G$618,"<>") | F4: =COUNTIFS('Data filtrees'!$B$2:$B$618,$A4,'Data filtrees'!$C$2:$C$618,5,'Data filtrees'!$G$2:$G$618,"<>") | G4: =COUNTIFS('Data filtrees'!$B$2:$B$618,$A4,'Data filtrees'!$C$2:$C$618,6,'Data filtrees'!$G$2:$G$618,"<>") | H4: =COUNTIFS('Data filtrees'!$B$2:$B$618,$A4,'Data filtrees'!$C$2:$C$618,7,'Data filtrees'!$G$2:$G$618,"<>") | I4: =COUNTIFS('Data filtrees'!$B$2:$B$618,$A4,'Data filtrees'!$C$2:$C$618,8,'Data filtrees'!$G$2:$G$618,"<>") | J4: =COUNTIFS('Data filtrees'!$B$2:$B$618,$A4,'Data filtrees'!$C$2:$C$618,9,'Data filtrees'!$G$2:$G$618,"<>") | K4: =COUNTIFS('Data filtrees'!$B$2:$B$618,$A4,'Data filtrees'!$C$2:$C$618,10,'Data filtrees'!$G$2:$G$618,"<>") | L4: =COUNTIFS('Data filtrees'!$B$2:$B$618,$A4,'Data filtrees'!$C$2:$C$618,11,'Data filtrees'!$G$2:$G$618,"<>") | M4: =COUNTIFS('Data filtrees'!$B$2:$B$618,$A4,'Data filtrees'!$C$2:$C$618,12,'Data filtrees'!$G$2:$G$618,"<>")
A6: MOYENNE | B6: 1 | C6: 2 | D6: 3 | E6: 4 | F6: 5 | G6: 6 | H6: 7 | I6: 8 | J6: 9 | K6: 10 | L6: 11 | M6: 12
A7: 2RS | B7: =IF(B3>=5,AVERAGEIFS('Data filtrees'!$G$2:$G$618,'Data filtrees'!$B$2:$B$618,$A3,'Data filtrees'!$C$2:$C$618,1),AVERAGEIFS('Data filtrees'!$G$2:$G$618,'Data filtrees'!$C$2:$C$618,1)) | C7: =IF(C3>=5,AVERAGEIFS('Data filtrees'!$G$2:$G$618,'Data filtrees'!$B$2:$B$618,$A3,'Data filtrees'!$C$2:$C$618,2),AVERAGEIFS('Data filtrees'!$G$2:$G$618,'Data filtrees'!$C$2:$C$618,2)) | D7: =IF(D3>=5,AVERAGEIFS('Data filtrees'!$G$2:$G$618,'Data filtrees'!$B$2:$B$618,$A3,'Data filtrees'!$C$2:$C$618,3),AVERAGEIFS('Data filtrees'!$G$2:$G$618,'Data filtrees'!$C$2:$C$618,3)) | E7: =IF(E3>=5,AVERAGEIFS('Data filtrees'!$G$2:$G$618,'Data filtrees'!$B$2:$B$618,$A3,'Data filtrees'!$C$2:$C$618,4),AVERAGEIFS('Data filtrees'!$G$2:$G$618,'Data filtrees'!$C$2:$C$618,4)) | F7: =IF(F3>=5,AVERAGEIFS('Data filtrees'!$G$2:$G$618,'Data filtrees'!$B$2:$B$618,$A3,'Data filtrees'!$C$2:$C$618,5),AVERAGEIFS('Data filtrees'!$G$2:$G$618,'Data filtrees'!$C$2:$C$618,5)) | G7: =IF(G3>=5,AVERAGEIFS('Data filtrees'!$G$2:$G$618,'Data filtrees'!$B$2:$B$618,$A3,'Data filtrees'!$C$2:$C$618,6),AVERAGEIFS('Data filtrees'!$G$2:$G$618,'Data filtrees'!$C$2:$C$618,6)) | H7: =IF(H3>=5,AVERAGEIFS('Data filtrees'!$G$2:$G$618,'Data filtrees'!$B$2:$B$618,$A3,'Data filtrees'!$C$2:$C$618,7),AVERAGEIFS('Data filtrees'!$G$2:$G$618,'Data filtrees'!$C$2:$C$618,7)) | I7: =IF(I3>=5,AVERAGEIFS('Data filtrees'!$G$2:$G$618,'Data filtrees'!$B$2:$B$618,$A3,'Data filtrees'!$C$2:$C$618,8),AVERAGEIFS('Data filtrees'!$G$2:$G$618,'Data filtrees'!$C$2:$C$618,8)) | J7: =IF(J3>=5,AVERAGEIFS('Data filtrees'!$G$2:$G$618,'Data filtrees'!$B$2:$B$618,$A3,'Data filtrees'!$C$2:$C$618,9),AVERAGEIFS('Data filtrees'!$G$2:$G$618,'Data filtrees'!$C$2:$C$618,9)) | K7: =IF(K3>=5,AVERAGEIFS('Data filtrees'!$G$2:$G$618,'Data filtrees'!$B$2:$B$618,$A3,'Data filtrees'!$C$2:$C$618,10),AVERAGEIFS('Data filtrees'!$G$2:$G$618,'Data filtrees'!$C$2:$C$618,10)) | L7: =IF(L3>=5,AVERAGEIFS('Data filtrees'!$G$2:$G$618,'Data filtrees'!$B$2:$B$618,$A3,'Data filtrees'!$C$2:$C$618,11),AVERAGEIFS('Data filtrees'!$G$2:$G$618,'Data filtrees'!$C$2:$C$618,11)) | M7: =IF(M3>=5,AVERAGEIFS('Data filtrees'!$G$2:$G$618,'Data filtrees'!$B$2:$B$618,$A3,'Data filtrees'!$C$2:$C$618,12),AVERAGEIFS('Data filtrees'!$G$2:$G$618,'Data filtrees'!$C$2:$C$618,12))
A8: IBON | B8: =IF(B4>=5,AVERAGEIFS('Data filtrees'!$G$2:$G$618,'Data filtrees'!$B$2:$B$618,$A4,'Data filtrees'!$C$2:$C$618,1),AVERAGEIFS('Data filtrees'!$G$2:$G$618,'Data filtrees'!$C$2:$C$618,1)) | C8: =IF(C4>=5,AVERAGEIFS('Data filtrees'!$G$2:$G$618,'Data filtrees'!$B$2:$B$618,$A4,'Data filtrees'!$C$2:$C$618,2),AVERAGEIFS('Data filtrees'!$G$2:$G$618,'Data filtrees'!$C$2:$C$618,2)) | D8: =IF(D4>=5,AVERAGEIFS('Data filtrees'!$G$2:$G$618,'Data filtrees'!$B$2:$B$618,$A4,'Data filtrees'!$C$2:$C$618,3),AVERAGEIFS('Data filtrees'!$G$2:$G$618,'Data filtrees'!$C$2:$C$618,3)) | E8: =IF(E4>=5,AVERAGEIFS('Data filtrees'!$G$2:$G$618,'Data filtrees'!$B$2:$B$618,$A4,'Data filtrees'!$C$2:$C$618,4),AVERAGEIFS('Data filtrees'!$G$2:$G$618,'Data filtrees'!$C$2:$C$618,4)) | F8: =IF(F4>=5,AVERAGEIFS('Data filtrees'!$G$2:$G$618,'Data filtrees'!$B$2:$B$618,$A4,'Data filtrees'!$C$2:$C$618,5),AVERAGEIFS('Data filtrees'!$G$2:$G$618,'Data filtrees'!$C$2:$C$618,5)) | G8: =IF(G4>=5,AVERAGEIFS('Data filtrees'!$G$2:$G$618,'Data filtrees'!$B$2:$B$618,$A4,'Data filtrees'!$C$2:$C$618,6),AVERAGEIFS('Data filtrees'!$G$2:$G$618,'Data filtrees'!$C$2:$C$618,6)) | H8: =IF(H4>=5,AVERAGEIFS('Data filtrees'!$G$2:$G$618,'Data filtrees'!$B$2:$B$618,$A4,'Data filtrees'!$C$2:$C$618,7),AVERAGEIFS('Data filtrees'!$G$2:$G$618,'Data filtrees'!$C$2:$C$618,7)) | I8: =IF(I4>=5,AVERAGEIFS('Data filtrees'!$G$2:$G$618,'Data filtrees'!$B$2:$B$618,$A4,'Data filtrees'!$C$2:$C$618,8),AVERAGEIFS('Data filtrees'!$G$2:$G$618,'Data filtrees'!$C$2:$C$618,8)) | J8: =IF(J4>=5,AVERAGEIFS('Data filtrees'!$G$2:$G$618,'Data filtrees'!$B$2:$B$618,$A4,'Data filtrees'!$C$2:$C$618,9),AVERAGEIFS('Data filtrees'!$G$2:$G$618,'Data filtrees'!$C$2:$C$618,9)) | K8: =IF(K4>=5,AVERAGEIFS('Data filtrees'!$G$2:$G$618,'Data filtrees'!$B$2:$B$618,$A4,'Data filtrees'!$C$2:$C$618,10),AVERAGEIFS('Data filtrees'!$G$2:$G$618,'Data filtrees'!$C$2:$C$618,10)) | L8: =IF(L4>=5,AVERAGEIFS('Data filtrees'!$G$2:$G$618,'Data filtrees'!$B$2:$B$618,$A4,'Data filtrees'!$C$2:$C$618,11),AVERAGEIFS('Data filtrees'!$G$2:$G$618,'Data filtrees'!$C$2:$C$618,11)) | M8: =IF(M4>=5,AVERAGEIFS('Data filtrees'!$G$2:$G$618,'Data filtrees'!$B$2:$B$618,$A4,'Data filtrees'!$C$2:$C$618,12),AVERAGEIFS('Data filtrees'!$G$2:$G$618,'Data filtrees'!$C$2:$C$618,12))
A9: monthly_average | B9: =AVERAGEIFS('Data filtrees'!$G$2:$G$618,'Data filtrees'!$C$2:$C$618,1) | C9: =AVERAGEIFS('Data filtrees'!$G$2:$G$618,'Data filtrees'!$C$2:$C$618,2) | D9: =AVERAGEIFS('Data filtrees'!$G$2:$G$618,'Data filtrees'!$C$2:$C$618,3) | E9: =AVERAGEIFS('Data filtrees'!$G$2:$G$618,'Data filtrees'!$C$2:$C$618,4) | F9: =AVERAGEIFS('Data filtrees'!$G$2:$G$618,'Data filtrees'!$C$2:$C$618,5) | G9: =AVERAGEIFS('Data filtrees'!$G$2:$G$618,'Data filtrees'!$C$2:$C$618,6) | H9: =AVERAGEIFS('Data filtrees'!$G$2:$G$618,'Data filtrees'!$C$2:$C$618,7) | I9: =AVERAGEIFS('Data filtrees'!$G$2:$G$618,'Data filtrees'!$C$2:$C$618,8) | J9: =AVERAGEIFS('Data filtrees'!$G$2:$G$618,'Data filtrees'!$C$2:$C$618,9) | K9: =AVERAGEIFS('Data filtrees'!$G$2:$G$618,'Data filtrees'!$C$2:$C$618,10) | L9: =AVERAGEIFS('Data filtrees'!$G$2:$G$618,'Data filtrees'!$C$2:$C$618,11) | M9: =AVERAGEIFS('Data filtrees'!$G$2:$G$618,'Data filtrees'!$C$2:$C$618,12)
A11: Au moins 5 couches : moyenne du cahier des charges. En dessous : moyenne du mois, tous cahiers des charges confondus.

Sheet goods_weight
A1: Poids d'orge — nombre de couches, puis moyenne
A2: NB | B2: 1 | C2: 2 | D2: 3 | E2: 4 | F2: 5 | G2: 6 | H2: 7 | I2: 8 | J2: 9 | K2: 10 | L2: 11 | M2: 12
A3: 2RS | B3: =COUNTIFS('Data filtrees'!$B$2:$B$618,$A3,'Data filtrees'!$C$2:$C$618,1,'Data filtrees'!$H$2:$H$618,"<>") | C3: =COUNTIFS('Data filtrees'!$B$2:$B$618,$A3,'Data filtrees'!$C$2:$C$618,2,'Data filtrees'!$H$2:$H$618,"<>") | D3: =COUNTIFS('Data filtrees'!$B$2:$B$618,$A3,'Data filtrees'!$C$2:$C$618,3,'Data filtrees'!$H$2:$H$618,"<>") | E3: =COUNTIFS('Data filtrees'!$B$2:$B$618,$A3,'Data filtrees'!$C$2:$C$618,4,'Data filtrees'!$H$2:$H$618,"<>") | F3: =COUNTIFS('Data filtrees'!$B$2:$B$618,$A3,'Data filtrees'!$C$2:$C$618,5,'Data filtrees'!$H$2:$H$618,"<>") | G3: =COUNTIFS('Data filtrees'!$B$2:$B$618,$A3,'Data filtrees'!$C$2:$C$618,6,'Data filtrees'!$H$2:$H$618,"<>") | H3: =COUNTIFS('Data filtrees'!$B$2:$B$618,$A3,'Data filtrees'!$C$2:$C$618,7,'Data filtrees'!$H$2:$H$618,"<>") | I3: =COUNTIFS('Data filtrees'!$B$2:$B$618,$A3,'Data filtrees'!$C$2:$C$618,8,'Data filtrees'!$H$2:$H$618,"<>") | J3: =COUNTIFS('Data filtrees'!$B$2:$B$618,$A3,'Data filtrees'!$C$2:$C$618,9,'Data filtrees'!$H$2:$H$618,"<>") | K3: =COUNTIFS('Data filtrees'!$B$2:$B$618,$A3,'Data filtrees'!$C$2:$C$618,10,'Data filtrees'!$H$2:$H$618,"<>") | L3: =COUNTIFS('Data filtrees'!$B$2:$B$618,$A3,'Data filtrees'!$C$2:$C$618,11,'Data filtrees'!$H$2:$H$618,"<>") | M3: =COUNTIFS('Data filtrees'!$B$2:$B$618,$A3,'Data filtrees'!$C$2:$C$618,12,'Data filtrees'!$H$2:$H$618,"<>")
A4: IBON | B4: =COUNTIFS('Data filtrees'!$B$2:$B$618,$A4,'Data filtrees'!$C$2:$C$618,1,'Data filtrees'!$H$2:$H$618,"<>") | C4: =COUNTIFS('Data filtrees'!$B$2:$B$618,$A4,'Data filtrees'!$C$2:$C$618,2,'Data filtrees'!$H$2:$H$618,"<>") | D4: =COUNTIFS('Data filtrees'!$B$2:$B$618,$A4,'Data filtrees'!$C$2:$C$618,3,'Data filtrees'!$H$2:$H$618,"<>") | E4: =COUNTIFS('Data filtrees'!$B$2:$B$618,$A4,'Data filtrees'!$C$2:$C$618,4,'Data filtrees'!$H$2:$H$618,"<>") | F4: =COUNTIFS('Data filtrees'!$B$2:$B$618,$A4,'Data filtrees'!$C$2:$C$618,5,'Data filtrees'!$H$2:$H$618,"<>") | G4: =COUNTIFS('Data filtrees'!$B$2:$B$618,$A4,'Data filtrees'!$C$2:$C$618,6,'Data filtrees'!$H$2:$H$618,"<>") | H4: =COUNTIFS('Data filtrees'!$B$2:$B$618,$A4,'Data filtrees'!$C$2:$C$618,7,'Data filtrees'!$H$2:$H$618,"<>") | I4: =COUNTIFS('Data filtrees'!$B$2:$B$618,$A4,'Data filtrees'!$C$2:$C$618,8,'Data filtrees'!$H$2:$H$618,"<>") | J4: =COUNTIFS('Data filtrees'!$B$2:$B$618,$A4,'Data filtrees'!$C$2:$C$618,9,'Data filtrees'!$H$2:$H$618,"<>") | K4: =COUNTIFS('Data filtrees'!$B$2:$B$618,$A4,'Data filtrees'!$C$2:$C$618,10,'Data filtrees'!$H$2:$H$618,"<>") | L4: =COUNTIFS('Data filtrees'!$B$2:$B$618,$A4,'Data filtrees'!$C$2:$C$618,11,'Data filtrees'!$H$2:$H$618,"<>") | M4: =COUNTIFS('Data filtrees'!$B$2:$B$618,$A4,'Data filtrees'!$C$2:$C$618,12,'Data filtrees'!$H$2:$H$618,"<>")
A6: MOYENNE | B6: 1 | C6: 2 | D6: 3 | E6: 4 | F6: 5 | G6: 6 | H6: 7 | I6: 8 | J6: 9 | K6: 10 | L6: 11 | M6: 12
A7: 2RS | B7: =IF(B3>=5,AVERAGEIFS('Data filtrees'!$H$2:$H$618,'Data filtrees'!$B$2:$B$618,$A3,'Data filtrees'!$C$2:$C$618,1),AVERAGEIFS('Data filtrees'!$H$2:$H$618,'Data filtrees'!$C$2:$C$618,1)) | C7: =IF(C3>=5,AVERAGEIFS('Data filtrees'!$H$2:$H$618,'Data filtrees'!$B$2:$B$618,$A3,'Data filtrees'!$C$2:$C$618,2),AVERAGEIFS('Data filtrees'!$H$2:$H$618,'Data filtrees'!$C$2:$C$618,2)) | D7: =IF(D3>=5,AVERAGEIFS('Data filtrees'!$H$2:$H$618,'Data filtrees'!$B$2:$B$618,$A3,'Data filtrees'!$C$2:$C$618,3),AVERAGEIFS('Data filtrees'!$H$2:$H$618,'Data filtrees'!$C$2:$C$618,3)) | E7: =IF(E3>=5,AVERAGEIFS('Data filtrees'!$H$2:$H$618,'Data filtrees'!$B$2:$B$618,$A3,'Data filtrees'!$C$2:$C$618,4),AVERAGEIFS('Data filtrees'!$H$2:$H$618,'Data filtrees'!$C$2:$C$618,4)) | F7: =IF(F3>=5,AVERAGEIFS('Data filtrees'!$H$2:$H$618,'Data filtrees'!$B$2:$B$618,$A3,'Data filtrees'!$C$2:$C$618,5),AVERAGEIFS('Data filtrees'!$H$2:$H$618,'Data filtrees'!$C$2:$C$618,5)) | G7: =IF(G3>=5,AVERAGEIFS('Data filtrees'!$H$2:$H$618,'Data filtrees'!$B$2:$B$618,$A3,'Data filtrees'!$C$2:$C$618,6),AVERAGEIFS('Data filtrees'!$H$2:$H$618,'Data filtrees'!$C$2:$C$618,6)) | H7: =IF(H3>=5,AVERAGEIFS('Data filtrees'!$H$2:$H$618,'Data filtrees'!$B$2:$B$618,$A3,'Data filtrees'!$C$2:$C$618,7),AVERAGEIFS('Data filtrees'!$H$2:$H$618,'Data filtrees'!$C$2:$C$618,7)) | I7: =IF(I3>=5,AVERAGEIFS('Data filtrees'!$H$2:$H$618,'Data filtrees'!$B$2:$B$618,$A3,'Data filtrees'!$C$2:$C$618,8),AVERAGEIFS('Data filtrees'!$H$2:$H$618,'Data filtrees'!$C$2:$C$618,8)) | J7: =IF(J3>=5,AVERAGEIFS('Data filtrees'!$H$2:$H$618,'Data filtrees'!$B$2:$B$618,$A3,'Data filtrees'!$C$2:$C$618,9),AVERAGEIFS('Data filtrees'!$H$2:$H$618,'Data filtrees'!$C$2:$C$618,9)) | K7: =IF(K3>=5,AVERAGEIFS('Data filtrees'!$H$2:$H$618,'Data filtrees'!$B$2:$B$618,$A3,'Data filtrees'!$C$2:$C$618,10),AVERAGEIFS('Data filtrees'!$H$2:$H$618,'Data filtrees'!$C$2:$C$618,10)) | L7: =IF(L3>=5,AVERAGEIFS('Data filtrees'!$H$2:$H$618,'Data filtrees'!$B$2:$B$618,$A3,'Data filtrees'!$C$2:$C$618,11),AVERAGEIFS('Data filtrees'!$H$2:$H$618,'Data filtrees'!$C$2:$C$618,11)) | M7: =IF(M3>=5,AVERAGEIFS('Data filtrees'!$H$2:$H$618,'Data filtrees'!$B$2:$B$618,$A3,'Data filtrees'!$C$2:$C$618,12),AVERAGEIFS('Data filtrees'!$H$2:$H$618,'Data filtrees'!$C$2:$C$618,12))
A8: IBON | B8: =IF(B4>=5,AVERAGEIFS('Data filtrees'!$H$2:$H$618,'Data filtrees'!$B$2:$B$618,$A4,'Data filtrees'!$C$2:$C$618,1),AVERAGEIFS('Data filtrees'!$H$2:$H$618,'Data filtrees'!$C$2:$C$618,1)) | C8: =IF(C4>=5,AVERAGEIFS('Data filtrees'!$H$2:$H$618,'Data filtrees'!$B$2:$B$618,$A4,'Data filtrees'!$C$2:$C$618,2),AVERAGEIFS('Data filtrees'!$H$2:$H$618,'Data filtrees'!$C$2:$C$618,2)) | D8: =IF(D4>=5,AVERAGEIFS('Data filtrees'!$H$2:$H$618,'Data filtrees'!$B$2:$B$618,$A4,'Data filtrees'!$C$2:$C$618,3),AVERAGEIFS('Data filtrees'!$H$2:$H$618,'Data filtrees'!$C$2:$C$618,3)) | E8: =IF(E4>=5,AVERAGEIFS('Data filtrees'!$H$2:$H$618,'Data filtrees'!$B$2:$B$618,$A4,'Data filtrees'!$C$2:$C$618,4),AVERAGEIFS('Data filtrees'!$H$2:$H$618,'Data filtrees'!$C$2:$C$618,4)) | F8: =IF(F4>=5,AVERAGEIFS('Data filtrees'!$H$2:$H$618,'Data filtrees'!$B$2:$B$618,$A4,'Data filtrees'!$C$2:$C$618,5),AVERAGEIFS('Data filtrees'!$H$2:$H$618,'Data filtrees'!$C$2:$C$618,5)) | G8: =IF(G4>=5,AVERAGEIFS('Data filtrees'!$H$2:$H$618,'Data filtrees'!$B$2:$B$618,$A4,'Data filtrees'!$C$2:$C$618,6),AVERAGEIFS('Data filtrees'!$H$2:$H$618,'Data filtrees'!$C$2:$C$618,6)) | H8: =IF(H4>=5,AVERAGEIFS('Data filtrees'!$H$2:$H$618,'Data filtrees'!$B$2:$B$618,$A4,'Data filtrees'!$C$2:$C$618,7),AVERAGEIFS('Data filtrees'!$H$2:$H$618,'Data filtrees'!$C$2:$C$618,7)) | I8: =IF(I4>=5,AVERAGEIFS('Data filtrees'!$H$2:$H$618,'Data filtrees'!$B$2:$B$618,$A4,'Data filtrees'!$C$2:$C$618,8),AVERAGEIFS('Data filtrees'!$H$2:$H$618,'Data filtrees'!$C$2:$C$618,8)) | J8: =IF(J4>=5,AVERAGEIFS('Data filtrees'!$H$2:$H$618,'Data filtrees'!$B$2:$B$618,$A4,'Data filtrees'!$C$2:$C$618,9),AVERAGEIFS('Data filtrees'!$H$2:$H$618,'Data filtrees'!$C$2:$C$618,9)) | K8: =IF(K4>=5,AVERAGEIFS('Data filtrees'!$H$2:$H$618,'Data filtrees'!$B$2:$B$618,$A4,'Data filtrees'!$C$2:$C$618,10),AVERAGEIFS('Data filtrees'!$H$2:$H$618,'Data filtrees'!$C$2:$C$618,10)) | L8: =IF(L4>=5,AVERAGEIFS('Data filtrees'!$H$2:$H$618,'Data filtrees'!$B$2:$B$618,$A4,'Data filtrees'!$C$2:$C$618,11),AVERAGEIFS('Data filtrees'!$H$2:$H$618,'Data filtrees'!$C$2:$C$618,11)) | M8: =IF(M4>=5,AVERAGEIFS('Data filtrees'!$H$2:$H$618,'Data filtrees'!$B$2:$B$618,$A4,'Data filtrees'!$C$2:$C$618,12),AVERAGEIFS('Data filtrees'!$H$2:$H$618,'Data filtrees'!$C$2:$C$618,12))
A9: monthly_average | B9: =AVERAGEIFS('Data filtrees'!$H$2:$H$618,'Data filtrees'!$C$2:$C$618,1) | C9: =AVERAGEIFS('Data filtrees'!$H$2:$H$618,'Data filtrees'!$C$2:$C$618,2) | D9: =AVERAGEIFS('Data filtrees'!$H$2:$H$618,'Data filtrees'!$C$2:$C$618,3) | E9: =AVERAGEIFS('Data filtrees'!$H$2:$H$618,'Data filtrees'!$C$2:$C$618,4) | F9: =AVERAGEIFS('Data filtrees'!$H$2:$H$618,'Data filtrees'!$C$2:$C$618,5) | G9: =AVERAGEIFS('Data filtrees'!$H$2:$H$618,'Data filtrees'!$C$2:$C$618,6) | H9: =AVERAGEIFS('Data filtrees'!$H$2:$H$618,'Data filtrees'!$C$2:$C$618,7) | I9: =AVERAGEIFS('Data filtrees'!$H$2:$H$618,'Data filtrees'!$C$2:$C$618,8) | J9: =AVERAGEIFS('Data filtrees'!$H$2:$H$618,'Data filtrees'!$C$2:$C$618,9) | K9: =AVERAGEIFS('Data filtrees'!$H$2:$H$618,'Data filtrees'!$C$2:$C$618,10) | L9: =AVERAGEIFS('Data filtrees'!$H$2:$H$618,'Data filtrees'!$C$2:$C$618,11) | M9: =AVERAGEIFS('Data filtrees'!$H$2:$H$618,'Data filtrees'!$C$2:$C$618,12)
A11: Au moins 5 couches : moyenne du cahier des charges. En dessous : moyenne du mois, tous cahiers des charges confondus.

Sheet goods_moisture
A1: Humidite de l'orge — nombre de couches, puis moyenne
A2: NB | B2: 1 | C2: 2 | D2: 3 | E2: 4 | F2: 5 | G2: 6 | H2: 7 | I2: 8 | J2: 9 | K2: 10 | L2: 11 | M2: 12
A3: 2RS | B3: =COUNTIFS('Data filtrees'!$B$2:$B$618,$A3,'Data filtrees'!$C$2:$C$618,1,'Data filtrees'!$I$2:$I$618,"<>") | C3: =COUNTIFS('Data filtrees'!$B$2:$B$618,$A3,'Data filtrees'!$C$2:$C$618,2,'Data filtrees'!$I$2:$I$618,"<>") | D3: =COUNTIFS('Data filtrees'!$B$2:$B$618,$A3,'Data filtrees'!$C$2:$C$618,3,'Data filtrees'!$I$2:$I$618,"<>") | E3: =COUNTIFS('Data filtrees'!$B$2:$B$618,$A3,'Data filtrees'!$C$2:$C$618,4,'Data filtrees'!$I$2:$I$618,"<>") | F3: =COUNTIFS('Data filtrees'!$B$2:$B$618,$A3,'Data filtrees'!$C$2:$C$618,5,'Data filtrees'!$I$2:$I$618,"<>") | G3: =COUNTIFS('Data filtrees'!$B$2:$B$618,$A3,'Data filtrees'!$C$2:$C$618,6,'Data filtrees'!$I$2:$I$618,"<>") | H3: =COUNTIFS('Data filtrees'!$B$2:$B$618,$A3,'Data filtrees'!$C$2:$C$618,7,'Data filtrees'!$I$2:$I$618,"<>") | I3: =COUNTIFS('Data filtrees'!$B$2:$B$618,$A3,'Data filtrees'!$C$2:$C$618,8,'Data filtrees'!$I$2:$I$618,"<>") | J3: =COUNTIFS('Data filtrees'!$B$2:$B$618,$A3,'Data filtrees'!$C$2:$C$618,9,'Data filtrees'!$I$2:$I$618,"<>") | K3: =COUNTIFS('Data filtrees'!$B$2:$B$618,$A3,'Data filtrees'!$C$2:$C$618,10,'Data filtrees'!$I$2:$I$618,"<>") | L3: =COUNTIFS('Data filtrees'!$B$2:$B$618,$A3,'Data filtrees'!$C$2:$C$618,11,'Data filtrees'!$I$2:$I$618,"<>") | M3: =COUNTIFS('Data filtrees'!$B$2:$B$618,$A3,'Data filtrees'!$C$2:$C$618,12,'Data filtrees'!$I$2:$I$618,"<>")
A4: IBON | B4: =COUNTIFS('Data filtrees'!$B$2:$B$618,$A4,'Data filtrees'!$C$2:$C$618,1,'Data filtrees'!$I$2:$I$618,"<>") | C4: =COUNTIFS('Data filtrees'!$B$2:$B$618,$A4,'Data filtrees'!$C$2:$C$618,2,'Data filtrees'!$I$2:$I$618,"<>") | D4: =COUNTIFS('Data filtrees'!$B$2:$B$618,$A4,'Data filtrees'!$C$2:$C$618,3,'Data filtrees'!$I$2:$I$618,"<>") | E4: =COUNTIFS('Data filtrees'!$B$2:$B$618,$A4,'Data filtrees'!$C$2:$C$618,4,'Data filtrees'!$I$2:$I$618,"<>") | F4: =COUNTIFS('Data filtrees'!$B$2:$B$618,$A4,'Data filtrees'!$C$2:$C$618,5,'Data filtrees'!$I$2:$I$618,"<>") | G4: =COUNTIFS('Data filtrees'!$B$2:$B$618,$A4,'Data filtrees'!$C$2:$C$618,6,'Data filtrees'!$I$2:$I$618,"<>") | H4: =COUNTIFS('Data filtrees'!$B$2:$B$618,$A4,'Data filtrees'!$C$2:$C$618,7,'Data filtrees'!$I$2:$I$618,"<>") | I4: =COUNTIFS('Data filtrees'!$B$2:$B$618,$A4,'Data filtrees'!$C$2:$C$618,8,'Data filtrees'!$I$2:$I$618,"<>") | J4: =COUNTIFS('Data filtrees'!$B$2:$B$618,$A4,'Data filtrees'!$C$2:$C$618,9,'Data filtrees'!$I$2:$I$618,"<>") | K4: =COUNTIFS('Data filtrees'!$B$2:$B$618,$A4,'Data filtrees'!$C$2:$C$618,10,'Data filtrees'!$I$2:$I$618,"<>") | L4: =COUNTIFS('Data filtrees'!$B$2:$B$618,$A4,'Data filtrees'!$C$2:$C$618,11,'Data filtrees'!$I$2:$I$618,"<>") | M4: =COUNTIFS('Data filtrees'!$B$2:$B$618,$A4,'Data filtrees'!$C$2:$C$618,12,'Data filtrees'!$I$2:$I$618,"<>")
A6: MOYENNE | B6: 1 | C6: 2 | D6: 3 | E6: 4 | F6: 5 | G6: 6 | H6: 7 | I6: 8 | J6: 9 | K6: 10 | L6: 11 | M6: 12
A7: 2RS | B7: =IF(B3>=5,AVERAGEIFS('Data filtrees'!$I$2:$I$618,'Data filtrees'!$B$2:$B$618,$A3,'Data filtrees'!$C$2:$C$618,1),AVERAGEIFS('Data filtrees'!$I$2:$I$618,'Data filtrees'!$C$2:$C$618,1)) | C7: =IF(C3>=5,AVERAGEIFS('Data filtrees'!$I$2:$I$618,'Data filtrees'!$B$2:$B$618,$A3,'Data filtrees'!$C$2:$C$618,2),AVERAGEIFS('Data filtrees'!$I$2:$I$618,'Data filtrees'!$C$2:$C$618,2)) | D7: =IF(D3>=5,AVERAGEIFS('Data filtrees'!$I$2:$I$618,'Data filtrees'!$B$2:$B$618,$A3,'Data filtrees'!$C$2:$C$618,3),AVERAGEIFS('Data filtrees'!$I$2:$I$618,'Data filtrees'!$C$2:$C$618,3)) | E7: =IF(E3>=5,AVERAGEIFS('Data filtrees'!$I$2:$I$618,'Data filtrees'!$B$2:$B$618,$A3,'Data filtrees'!$C$2:$C$618,4),AVERAGEIFS('Data filtrees'!$I$2:$I$618,'Data filtrees'!$C$2:$C$618,4)) | F7: =IF(F3>=5,AVERAGEIFS('Data filtrees'!$I$2:$I$618,'Data filtrees'!$B$2:$B$618,$A3,'Data filtrees'!$C$2:$C$618,5),AVERAGEIFS('Data filtrees'!$I$2:$I$618,'Data filtrees'!$C$2:$C$618,5)) | G7: =IF(G3>=5,AVERAGEIFS('Data filtrees'!$I$2:$I$618,'Data filtrees'!$B$2:$B$618,$A3,'Data filtrees'!$C$2:$C$618,6),AVERAGEIFS('Data filtrees'!$I$2:$I$618,'Data filtrees'!$C$2:$C$618,6)) | H7: =IF(H3>=5,AVERAGEIFS('Data filtrees'!$I$2:$I$618,'Data filtrees'!$B$2:$B$618,$A3,'Data filtrees'!$C$2:$C$618,7),AVERAGEIFS('Data filtrees'!$I$2:$I$618,'Data filtrees'!$C$2:$C$618,7)) | I7: =IF(I3>=5,AVERAGEIFS('Data filtrees'!$I$2:$I$618,'Data filtrees'!$B$2:$B$618,$A3,'Data filtrees'!$C$2:$C$618,8),AVERAGEIFS('Data filtrees'!$I$2:$I$618,'Data filtrees'!$C$2:$C$618,8)) | J7: =IF(J3>=5,AVERAGEIFS('Data filtrees'!$I$2:$I$618,'Data filtrees'!$B$2:$B$618,$A3,'Data filtrees'!$C$2:$C$618,9),AVERAGEIFS('Data filtrees'!$I$2:$I$618,'Data filtrees'!$C$2:$C$618,9)) | K7: =IF(K3>=5,AVERAGEIFS('Data filtrees'!$I$2:$I$618,'Data filtrees'!$B$2:$B$618,$A3,'Data filtrees'!$C$2:$C$618,10),AVERAGEIFS('Data filtrees'!$I$2:$I$618,'Data filtrees'!$C$2:$C$618,10)) | L7: =IF(L3>=5,AVERAGEIFS('Data filtrees'!$I$2:$I$618,'Data filtrees'!$B$2:$B$618,$A3,'Data filtrees'!$C$2:$C$618,11),AVERAGEIFS('Data filtrees'!$I$2:$I$618,'Data filtrees'!$C$2:$C$618,11)) | M7: =IF(M3>=5,AVERAGEIFS('Data filtrees'!$I$2:$I$618,'Data filtrees'!$B$2:$B$618,$A3,'Data filtrees'!$C$2:$C$618,12),AVERAGEIFS('Data filtrees'!$I$2:$I$618,'Data filtrees'!$C$2:$C$618,12))
A8: IBON | B8: =IF(B4>=5,AVERAGEIFS('Data filtrees'!$I$2:$I$618,'Data filtrees'!$B$2:$B$618,$A4,'Data filtrees'!$C$2:$C$618,1),AVERAGEIFS('Data filtrees'!$I$2:$I$618,'Data filtrees'!$C$2:$C$618,1)) | C8: =IF(C4>=5,AVERAGEIFS('Data filtrees'!$I$2:$I$618,'Data filtrees'!$B$2:$B$618,$A4,'Data filtrees'!$C$2:$C$618,2),AVERAGEIFS('Data filtrees'!$I$2:$I$618,'Data filtrees'!$C$2:$C$618,2)) | D8: =IF(D4>=5,AVERAGEIFS('Data filtrees'!$I$2:$I$618,'Data filtrees'!$B$2:$B$618,$A4,'Data filtrees'!$C$2:$C$618,3),AVERAGEIFS('Data filtrees'!$I$2:$I$618,'Data filtrees'!$C$2:$C$618,3)) | E8: =IF(E4>=5,AVERAGEIFS('Data filtrees'!$I$2:$I$618,'Data filtrees'!$B$2:$B$618,$A4,'Data filtrees'!$C$2:$C$618,4),AVERAGEIFS('Data filtrees'!$I$2:$I$618,'Data filtrees'!$C$2:$C$618,4)) | F8: =IF(F4>=5,AVERAGEIFS('Data filtrees'!$I$2:$I$618,'Data filtrees'!$B$2:$B$618,$A4,'Data filtrees'!$C$2:$C$618,5),AVERAGEIFS('Data filtrees'!$I$2:$I$618,'Data filtrees'!$C$2:$C$618,5)) | G8: =IF(G4>=5,AVERAGEIFS('Data filtrees'!$I$2:$I$618,'Data filtrees'!$B$2:$B$618,$A4,'Data filtrees'!$C$2:$C$618,6),AVERAGEIFS('Data filtrees'!$I$2:$I$618,'Data filtrees'!$C$2:$C$618,6)) | H8: =IF(H4>=5,AVERAGEIFS('Data filtrees'!$I$2:$I$618,'Data filtrees'!$B$2:$B$618,$A4,'Data filtrees'!$C$2:$C$618,7),AVERAGEIFS('Data filtrees'!$I$2:$I$618,'Data filtrees'!$C$2:$C$618,7)) | I8: =IF(I4>=5,AVERAGEIFS('Data filtrees'!$I$2:$I$618,'Data filtrees'!$B$2:$B$618,$A4,'Data filtrees'!$C$2:$C$618,8),AVERAGEIFS('Data filtrees'!$I$2:$I$618,'Data filtrees'!$C$2:$C$618,8)) | J8: =IF(J4>=5,AVERAGEIFS('Data filtrees'!$I$2:$I$618,'Data filtrees'!$B$2:$B$618,$A4,'Data filtrees'!$C$2:$C$618,9),AVERAGEIFS('Data filtrees'!$I$2:$I$618,'Data filtrees'!$C$2:$C$618,9)) | K8: =IF(K4>=5,AVERAGEIFS('Data filtrees'!$I$2:$I$618,'Data filtrees'!$B$2:$B$618,$A4,'Data filtrees'!$C$2:$C$618,10),AVERAGEIFS('Data filtrees'!$I$2:$I$618,'Data filtrees'!$C$2:$C$618,10)) | L8: =IF(L4>=5,AVERAGEIFS('Data filtrees'!$I$2:$I$618,'Data filtrees'!$B$2:$B$618,$A4,'Data filtrees'!$C$2:$C$618,11),AVERAGEIFS('Data filtrees'!$I$2:$I$618,'Data filtrees'!$C$2:$C$618,11)) | M8: =IF(M4>=5,AVERAGEIFS('Data filtrees'!$I$2:$I$618,'Data filtrees'!$B$2:$B$618,$A4,'Data filtrees'!$C$2:$C$618,12),AVERAGEIFS('Data filtrees'!$I$2:$I$618,'Data filtrees'!$C$2:$C$618,12))
A9: monthly_average | B9: =AVERAGEIFS('Data filtrees'!$I$2:$I$618,'Data filtrees'!$C$2:$C$618,1) | C9: =AVERAGEIFS('Data filtrees'!$I$2:$I$618,'Data filtrees'!$C$2:$C$618,2) | D9: =AVERAGEIFS('Data filtrees'!$I$2:$I$618,'Data filtrees'!$C$2:$C$618,3) | E9: =AVERAGEIFS('Data filtrees'!$I$2:$I$618,'Data filtrees'!$C$2:$C$618,4) | F9: =AVERAGEIFS('Data filtrees'!$I$2:$I$618,'Data filtrees'!$C$2:$C$618,5) | G9: =AVERAGEIFS('Data filtrees'!$I$2:$I$618,'Data filtrees'!$C$2:$C$618,6) | H9: =AVERAGEIFS('Data filtrees'!$I$2:$I$618,'Data filtrees'!$C$2:$C$618,7) | I9: =AVERAGEIFS('Data filtrees'!$I$2:$I$618,'Data filtrees'!$C$2:$C$618,8) | J9: =AVERAGEIFS('Data filtrees'!$I$2:$I$618,'Data filtrees'!$C$2:$C$618,9) | K9: =AVERAGEIFS('Data filtrees'!$I$2:$I$618,'Data filtrees'!$C$2:$C$618,10) | L9: =AVERAGEIFS('Data filtrees'!$I$2:$I$618,'Data filtrees'!$C$2:$C$618,11) | M9: =AVERAGEIFS('Data filtrees'!$I$2:$I$618,'Data filtrees'!$C$2:$C$618,12)
A11: Au moins 5 couches : moyenne du cahier des charges. En dessous : moyenne du mois, tous cahiers des charges confondus.

Sheet malt_moisture
A1: Humidite du malt — nombre de couches, puis moyenne
A2: NB | B2: 1 | C2: 2 | D2: 3 | E2: 4 | F2: 5 | G2: 6 | H2: 7 | I2: 8 | J2: 9 | K2: 10 | L2: 11 | M2: 12
A3: 2RS | B3: =COUNTIFS('Data filtrees'!$B$2:$B$618,$A3,'Data filtrees'!$C$2:$C$618,1,'Data filtrees'!$J$2:$J$618,"<>") | C3: =COUNTIFS('Data filtrees'!$B$2:$B$618,$A3,'Data filtrees'!$C$2:$C$618,2,'Data filtrees'!$J$2:$J$618,"<>") | D3: =COUNTIFS('Data filtrees'!$B$2:$B$618,$A3,'Data filtrees'!$C$2:$C$618,3,'Data filtrees'!$J$2:$J$618,"<>") | E3: =COUNTIFS('Data filtrees'!$B$2:$B$618,$A3,'Data filtrees'!$C$2:$C$618,4,'Data filtrees'!$J$2:$J$618,"<>") | F3: =COUNTIFS('Data filtrees'!$B$2:$B$618,$A3,'Data filtrees'!$C$2:$C$618,5,'Data filtrees'!$J$2:$J$618,"<>") | G3: =COUNTIFS('Data filtrees'!$B$2:$B$618,$A3,'Data filtrees'!$C$2:$C$618,6,'Data filtrees'!$J$2:$J$618,"<>") | H3: =COUNTIFS('Data filtrees'!$B$2:$B$618,$A3,'Data filtrees'!$C$2:$C$618,7,'Data filtrees'!$J$2:$J$618,"<>") | I3: =COUNTIFS('Data filtrees'!$B$2:$B$618,$A3,'Data filtrees'!$C$2:$C$618,8,'Data filtrees'!$J$2:$J$618,"<>") | J3: =COUNTIFS('Data filtrees'!$B$2:$B$618,$A3,'Data filtrees'!$C$2:$C$618,9,'Data filtrees'!$J$2:$J$618,"<>") | K3: =COUNTIFS('Data filtrees'!$B$2:$B$618,$A3,'Data filtrees'!$C$2:$C$618,10,'Data filtrees'!$J$2:$J$618,"<>") | L3: =COUNTIFS('Data filtrees'!$B$2:$B$618,$A3,'Data filtrees'!$C$2:$C$618,11,'Data filtrees'!$J$2:$J$618,"<>") | M3: =COUNTIFS('Data filtrees'!$B$2:$B$618,$A3,'Data filtrees'!$C$2:$C$618,12,'Data filtrees'!$J$2:$J$618,"<>")
A4: IBON | B4: =COUNTIFS('Data filtrees'!$B$2:$B$618,$A4,'Data filtrees'!$C$2:$C$618,1,'Data filtrees'!$J$2:$J$618,"<>") | C4: =COUNTIFS('Data filtrees'!$B$2:$B$618,$A4,'Data filtrees'!$C$2:$C$618,2,'Data filtrees'!$J$2:$J$618,"<>") | D4: =COUNTIFS('Data filtrees'!$B$2:$B$618,$A4,'Data filtrees'!$C$2:$C$618,3,'Data filtrees'!$J$2:$J$618,"<>") | E4: =COUNTIFS('Data filtrees'!$B$2:$B$618,$A4,'Data filtrees'!$C$2:$C$618,4,'Data filtrees'!$J$2:$J$618,"<>") | F4: =COUNTIFS('Data filtrees'!$B$2:$B$618,$A4,'Data filtrees'!$C$2:$C$618,5,'Data filtrees'!$J$2:$J$618,"<>") | G4: =COUNTIFS('Data filtrees'!$B$2:$B$618,$A4,'Data filtrees'!$C$2:$C$618,6,'Data filtrees'!$J$2:$J$618,"<>") | H4: =COUNTIFS('Data filtrees'!$B$2:$B$618,$A4,'Data filtrees'!$C$2:$C$618,7,'Data filtrees'!$J$2:$J$618,"<>") | I4: =COUNTIFS('Data filtrees'!$B$2:$B$618,$A4,'Data filtrees'!$C$2:$C$618,8,'Data filtrees'!$J$2:$J$618,"<>") | J4: =COUNTIFS('Data filtrees'!$B$2:$B$618,$A4,'Data filtrees'!$C$2:$C$618,9,'Data filtrees'!$J$2:$J$618,"<>") | K4: =COUNTIFS('Data filtrees'!$B$2:$B$618,$A4,'Data filtrees'!$C$2:$C$618,10,'Data filtrees'!$J$2:$J$618,"<>") | L4: =COUNTIFS('Data filtrees'!$B$2:$B$618,$A4,'Data filtrees'!$C$2:$C$618,11,'Data filtrees'!$J$2:$J$618,"<>") | M4: =COUNTIFS('Data filtrees'!$B$2:$B$618,$A4,'Data filtrees'!$C$2:$C$618,12,'Data filtrees'!$J$2:$J$618,"<>")
A6: MOYENNE | B6: 1 | C6: 2 | D6: 3 | E6: 4 | F6: 5 | G6: 6 | H6: 7 | I6: 8 | J6: 9 | K6: 10 | L6: 11 | M6: 12
A7: 2RS | B7: =IF(B3>=5,AVERAGEIFS('Data filtrees'!$J$2:$J$618,'Data filtrees'!$B$2:$B$618,$A3,'Data filtrees'!$C$2:$C$618,1),AVERAGEIFS('Data filtrees'!$J$2:$J$618,'Data filtrees'!$C$2:$C$618,1)) | C7: =IF(C3>=5,AVERAGEIFS('Data filtrees'!$J$2:$J$618,'Data filtrees'!$B$2:$B$618,$A3,'Data filtrees'!$C$2:$C$618,2),AVERAGEIFS('Data filtrees'!$J$2:$J$618,'Data filtrees'!$C$2:$C$618,2)) | D7: =IF(D3>=5,AVERAGEIFS('Data filtrees'!$J$2:$J$618,'Data filtrees'!$B$2:$B$618,$A3,'Data filtrees'!$C$2:$C$618,3),AVERAGEIFS('Data filtrees'!$J$2:$J$618,'Data filtrees'!$C$2:$C$618,3)) | E7: =IF(E3>=5,AVERAGEIFS('Data filtrees'!$J$2:$J$618,'Data filtrees'!$B$2:$B$618,$A3,'Data filtrees'!$C$2:$C$618,4),AVERAGEIFS('Data filtrees'!$J$2:$J$618,'Data filtrees'!$C$2:$C$618,4)) | F7: =IF(F3>=5,AVERAGEIFS('Data filtrees'!$J$2:$J$618,'Data filtrees'!$B$2:$B$618,$A3,'Data filtrees'!$C$2:$C$618,5),AVERAGEIFS('Data filtrees'!$J$2:$J$618,'Data filtrees'!$C$2:$C$618,5)) | G7: =IF(G3>=5,AVERAGEIFS('Data filtrees'!$J$2:$J$618,'Data filtrees'!$B$2:$B$618,$A3,'Data filtrees'!$C$2:$C$618,6),AVERAGEIFS('Data filtrees'!$J$2:$J$618,'Data filtrees'!$C$2:$C$618,6)) | H7: =IF(H3>=5,AVERAGEIFS('Data filtrees'!$J$2:$J$618,'Data filtrees'!$B$2:$B$618,$A3,'Data filtrees'!$C$2:$C$618,7),AVERAGEIFS('Data filtrees'!$J$2:$J$618,'Data filtrees'!$C$2:$C$618,7)) | I7: =IF(I3>=5,AVERAGEIFS('Data filtrees'!$J$2:$J$618,'Data filtrees'!$B$2:$B$618,$A3,'Data filtrees'!$C$2:$C$618,8),AVERAGEIFS('Data filtrees'!$J$2:$J$618,'Data filtrees'!$C$2:$C$618,8)) | J7: =IF(J3>=5,AVERAGEIFS('Data filtrees'!$J$2:$J$618,'Data filtrees'!$B$2:$B$618,$A3,'Data filtrees'!$C$2:$C$618,9),AVERAGEIFS('Data filtrees'!$J$2:$J$618,'Data filtrees'!$C$2:$C$618,9)) | K7: =IF(K3>=5,AVERAGEIFS('Data filtrees'!$J$2:$J$618,'Data filtrees'!$B$2:$B$618,$A3,'Data filtrees'!$C$2:$C$618,10),AVERAGEIFS('Data filtrees'!$J$2:$J$618,'Data filtrees'!$C$2:$C$618,10)) | L7: =IF(L3>=5,AVERAGEIFS('Data filtrees'!$J$2:$J$618,'Data filtrees'!$B$2:$B$618,$A3,'Data filtrees'!$C$2:$C$618,11),AVERAGEIFS('Data filtrees'!$J$2:$J$618,'Data filtrees'!$C$2:$C$618,11)) | M7: =IF(M3>=5,AVERAGEIFS('Data filtrees'!$J$2:$J$618,'Data filtrees'!$B$2:$B$618,$A3,'Data filtrees'!$C$2:$C$618,12),AVERAGEIFS('Data filtrees'!$J$2:$J$618,'Data filtrees'!$C$2:$C$618,12))
A8: IBON | B8: =IF(B4>=5,AVERAGEIFS('Data filtrees'!$J$2:$J$618,'Data filtrees'!$B$2:$B$618,$A4,'Data filtrees'!$C$2:$C$618,1),AVERAGEIFS('Data filtrees'!$J$2:$J$618,'Data filtrees'!$C$2:$C$618,1)) | C8: =IF(C4>=5,AVERAGEIFS('Data filtrees'!$J$2:$J$618,'Data filtrees'!$B$2:$B$618,$A4,'Data filtrees'!$C$2:$C$618,2),AVERAGEIFS('Data filtrees'!$J$2:$J$618,'Data filtrees'!$C$2:$C$618,2)) | D8: =IF(D4>=5,AVERAGEIFS('Data filtrees'!$J$2:$J$618,'Data filtrees'!$B$2:$B$618,$A4,'Data filtrees'!$C$2:$C$618,3),AVERAGEIFS('Data filtrees'!$J$2:$J$618,'Data filtrees'!$C$2:$C$618,3)) | E8: =IF(E4>=5,AVERAGEIFS('Data filtrees'!$J$2:$J$618,'Data filtrees'!$B$2:$B$618,$A4,'Data filtrees'!$C$2:$C$618,4),AVERAGEIFS('Data filtrees'!$J$2:$J$618,'Data filtrees'!$C$2:$C$618,4)) | F8: =IF(F4>=5,AVERAGEIFS('Data filtrees'!$J$2:$J$618,'Data filtrees'!$B$2:$B$618,$A4,'Data filtrees'!$C$2:$C$618,5),AVERAGEIFS('Data filtrees'!$J$2:$J$618,'Data filtrees'!$C$2:$C$618,5)) | G8: =IF(G4>=5,AVERAGEIFS('Data filtrees'!$J$2:$J$618,'Data filtrees'!$B$2:$B$618,$A4,'Data filtrees'!$C$2:$C$618,6),AVERAGEIFS('Data filtrees'!$J$2:$J$618,'Data filtrees'!$C$2:$C$618,6)) | H8: =IF(H4>=5,AVERAGEIFS('Data filtrees'!$J$2:$J$618,'Data filtrees'!$B$2:$B$618,$A4,'Data filtrees'!$C$2:$C$618,7),AVERAGEIFS('Data filtrees'!$J$2:$J$618,'Data filtrees'!$C$2:$C$618,7)) | I8: =IF(I4>=5,AVERAGEIFS('Data filtrees'!$J$2:$J$618,'Data filtrees'!$B$2:$B$618,$A4,'Data filtrees'!$C$2:$C$618,8),AVERAGEIFS('Data filtrees'!$J$2:$J$618,'Data filtrees'!$C$2:$C$618,8)) | J8: =IF(J4>=5,AVERAGEIFS('Data filtrees'!$J$2:$J$618,'Data filtrees'!$B$2:$B$618,$A4,'Data filtrees'!$C$2:$C$618,9),AVERAGEIFS('Data filtrees'!$J$2:$J$618,'Data filtrees'!$C$2:$C$618,9)) | K8: =IF(K4>=5,AVERAGEIFS('Data filtrees'!$J$2:$J$618,'Data filtrees'!$B$2:$B$618,$A4,'Data filtrees'!$C$2:$C$618,10),AVERAGEIFS('Data filtrees'!$J$2:$J$618,'Data filtrees'!$C$2:$C$618,10)) | L8: =IF(L4>=5,AVERAGEIFS('Data filtrees'!$J$2:$J$618,'Data filtrees'!$B$2:$B$618,$A4,'Data filtrees'!$C$2:$C$618,11),AVERAGEIFS('Data filtrees'!$J$2:$J$618,'Data filtrees'!$C$2:$C$618,11)) | M8: =IF(M4>=5,AVERAGEIFS('Data filtrees'!$J$2:$J$618,'Data filtrees'!$B$2:$B$618,$A4,'Data filtrees'!$C$2:$C$618,12),AVERAGEIFS('Data filtrees'!$J$2:$J$618,'Data filtrees'!$C$2:$C$618,12))
